Workbook

Sheet Test
A1: 6. SINIF KÜP SORULARI · RASTGELE TEST
A3: Soru sayısı | B3: 10 | C3: 1 ile 100 arası
A4: Konu | B4: Hepsi | C4: Listeden seçin
A5: Zorluk | B5: Hepsi | C5: Hepsi / Kolay / Orta / Zor
A6: Uygun soru (havuzda) | B6: =SUM('Soru Havuzu'!$J$2:$J$1001) -> 224 | C6: =IF(B6<B3,"Uyarı: havuzda yeterli soru yok, "&B6&" soru listelendi.","")
A8: Sarı hücreleri değiştirin. Yeni sorular için F9'a basın. Listeyi sabitlemek için: Kopyala → Değerleri Yapıştır.
A9: Ad Soyad: ................................. Sınıf: ........... Tarih: ....../....../......
A11: No | B11: Soru | C11: A) | D11: B) | E11: C) | F11: D) | G11: Konu | H11: Zorluk | J11: Havuz satırı
A12: =IF($J12="","",1) -> 1 | B12: =IF($J12="","",INDEX('Soru Havuzu'!$D$2:$D$1001,$J12)) -> Bir ayrıtı 2 cm olan küpün tüm ayrıtlarının uzunlukları toplamı kaç cm'dir? | C12: =IF($J12="","",INDEX('Soru Havuzu'!$E$2:$E$1001,$J12)) -> 16 | D12: =IF($J12="","",INDEX('Soru Havuzu'!$F$2:$F$1001,$J12)) -> 24 | E12: =IF($J12="","",INDEX('Soru Havuzu'!$G$2:$G$1001,$J12)) -> 8 | F12: =IF($J12="","",INDEX('Soru Havuzu'!$H$2:$H$1001,$J12)) -> 12 | G12: =IF($J12="","",INDEX('Soru Havuzu'!$B$2:$B$1001,$J12)) -> Küpün Özellikleri | H12: =IF($J12="","",INDEX('Soru Havuzu'!$C$2:$C$1001,$J12)) -> Orta | J12: =IF(1<=MIN($B$3,$B$6),MATCH(1,'Soru Havuzu'!$L$2:$L$1001,0),"") -> 177
A13: =IF($J13="","",2) -> 2 | B13: =IF($J13="","",INDEX('Soru Havuzu'!$D$2:$D$1001,$J13)) -> 7³ ifadesinin değeri kaçtır? | C13: =IF($J13="","",INDEX('Soru Havuzu'!$E$2:$E$1001,$J13)) -> 343 | D13: =IF($J13="","",INDEX('Soru Havuzu'!$F$2:$F$1001,$J13)) -> 49 | E13: =IF($J13="","",INDEX('Soru Havuzu'!$G$2:$G$1001,$J13)) -> 21 | F13: =IF($J13="","",INDEX('Soru Havuzu'!$H$2:$H$1001,$J13)) -> 350 | G13: =IF($J13="","",INDEX('Soru Havuzu'!$B$2:$B$1001,$J13)) -> Sayının Küpü | H13: =IF($J13="","",INDEX('Soru Havuzu'!$C$2:$C$1001,$J13)) -> Kolay | J13: =IF(2<=MIN($B$3,$B$6),MATCH(2,'Soru Havuzu'!$L$2:$L$1001,0),"") -> 7
A14: =IF($J14="","",3) -> 3 | B14: =IF($J14="","",INDEX('Soru Havuzu'!$D$2:$D$1001,$J14)) -> Bir ayrıtı 7 cm olan küpün tüm ayrıtlarının uzunlukları toplamı kaç cm'dir? | C14: =IF($J14="","",INDEX('Soru Havuzu'!$E$2:$E$1001,$J14)) -> 42 | D14: =IF($J14="","",INDEX('Soru Havuzu'!$F$2:$F$1001,$J14)) -> 56 | E14: =IF($J14="","",INDEX('Soru Havuzu'!$G$2:$G$1001,$J14)) -> 84 | F14: =IF($J14="","",INDEX('Soru Havuzu'!$H$2:$H$1001,$J14)) -> 343 | G14: =IF($J14="","",INDEX('Soru Havuzu'!$B$2:$B$1001,$J14)) -> Küpün Özellikleri | H14: =IF($J14="","",INDEX('Soru Havuzu'!$C$2:$C$1001,$J14)) -> Orta | J14: =IF(3<=MIN($B$3,$B$6),MATCH(3,'Soru Havuzu'!$L$2:$L$1001,0),"") -> 182
A15: =IF($J15="","",4) -> 4 | B15: =IF($J15="","",INDEX('Soru Havuzu'!$D$2:$D$1001,$J15)) -> Hacmi 8 cm³ olan küpün bir ayrıtı kaç cm'dir? | C15: =IF($J15="","",INDEX('Soru Havuzu'!$E$2:$E$1001,$J15)) -> 2 | D15: =IF($J15="","",INDEX('Soru Havuzu'!$F$2:$F$1001,$J15)) -> 3 | E15: =IF($J15="","",INDEX('Soru Havuzu'!$G$2:$G$1001,$J15)) -> 4 | F15: =IF($J15="","",INDEX('Soru Havuzu'!$H$2:$H$1001,$J15)) -> 1 | G15: =IF($J15="","",INDEX('Soru Havuzu'!$B$2:$B$1001,$J15)) -> Küpün Hacmi | H15: =IF($J15="","",INDEX('Soru Havuzu'!$C$2:$C$1001,$J15)) -> Orta | J15: =IF(4<=MIN($B$3,$B$6),MATCH(4,'Soru Havuzu'!$L$2:$L$1001,0),"") -> 119
A16: =IF($J16="","",5) -> 5 | B16: =IF($J16="","",INDEX('Soru Havuzu'!$D$2:$D$1001,$J16)) -> (2 + 2)³ ifadesinin değeri kaçtır? | C16: =IF($J16="","",INDEX('Soru Havuzu'!$E$2:$E$1001,$J16)) -> 10 | D16: =IF($J16="","",INDEX('Soru Havuzu'!$F$2:$F$1001,$J16)) -> 12 | E16: =IF($J16="","",INDEX('Soru Havuzu'!$G$2:$G$1001,$J16)) -> 16 | F16: =IF($J16="","",INDEX('Soru Havuzu'!$H$2:$H$1001,$J16)) -> 64 | G16: =IF($J16="","",INDEX('Soru Havuzu'!$B$2:$B$1001,$J16)) -> Sayının Küpü | H16: =IF($J16="","",INDEX('Soru Havuzu'!$C$2:$C$1001,$J16)) -> Zor | J16: =IF(5<=MIN($B$3,$B$6),MATCH(5,'Soru Havuzu'!$L$2:$L$1001,0),"") -> 84
A17: =IF($J17="","",6) -> 6 | B17: =IF($J17="","",INDEX('Soru Havuzu'!$D$2:$D$1001,$J17)) -> Aşağıdakilerden hangisinin değeri en büyüktür? | C17: =IF($J17="","",INDEX('Soru Havuzu'!$E$2:$E$1001,$J17)) -> 6² | D17: =IF($J17="","",INDEX('Soru Havuzu'!$F$2:$F$1001,$J17)) -> 7² | E17: =IF($J17="","",INDEX('Soru Havuzu'!$G$2:$G$1001,$J17)) -> 3² | F17: =IF($J17="","",INDEX('Soru Havuzu'!$H$2:$H$1001,$J17)) -> 10² | G17: =IF($J17="","",INDEX('Soru Havuzu'!$B$2:$B$1001,$J17)) -> Sayının Küpü | H17: =IF($J17="","",INDEX('Soru Havuzu'!$C$2:$C$1001,$J17)) -> Orta | J17: =IF(6<=MIN($B$3,$B$6),MATCH(6,'Soru Havuzu'!$L$2:$L$1001,0),"") -> 54
A18: =IF($J18="","",7) -> 7 | B18: =IF($J18="","",INDEX('Soru Havuzu'!$D$2:$D$1001,$J18)) -> 6³ ifadesinin anlamı aşağıdakilerden hangisidir? | C18: =IF($J18="","",INDEX('Soru Havuzu'!$E$2:$E$1001,$J18)) -> 6 · 3 | D18: =IF($J18="","",INDEX('Soru Havuzu'!$F$2:$F$1001,$J18)) -> 6 + 6 + 6 | E18: =IF($J18="","",INDEX('Soru Havuzu'!$G$2:$G$1001,$J18)) -> 6 · 6 · 6 | F18: =IF($J18="","",INDEX('Soru Havuzu'!$H$2:$H$1001,$J18)) -> 3 · 3 · 3 · 3 · 3 · 3 | G18: =IF($J18="","",INDEX('Soru Havuzu'!$B$2:$B$1001,$J18)) -> Sayının Küpü | H18: =IF($J18="","",INDEX('Soru Havuzu'!$C$2:$C$1001,$J18)) -> Kolay | J18: =IF(7<=MIN($B$3,$B$6),MATCH(7,'Soru Havuzu'!$L$2:$L$1001,0),"") -> 23
A19: =IF($J19="","",8) -> 8 | B19: =IF($J19="","",INDEX('Soru Havuzu'!$D$2:$D$1001,$J19)) -> Aşağıdakilerden hangisinin değeri en büyüktür? | C19: =IF($J19="","",INDEX('Soru Havuzu'!$E$2:$E$1001,$J19)) -> 5² | D19: =IF($J19="","",INDEX('Soru Havuzu'!$F$2:$F$1001,$J19)) -> 3² | E19: =IF($J19="","",INDEX('Soru Havuzu'!$G$2:$G$1001,$J19)) -> 7² | F19: =IF($J19="","",INDEX('Soru Havuzu'!$H$2:$H$1001,$J19)) -> 9² | G19: =IF($J19="","",INDEX('Soru Havuzu'!$B$2:$B$1001,$J19)) -> Sayının Küpü | H19: =IF($J19="","",INDEX('Soru Havuzu'!$C$2:$C$1001,$J19)) -> Orta | J19: =IF(8<=MIN($B$3,$B$6),MATCH(8,'Soru Havuzu'!$L$2:$L$1001,0),"") -> 56
A20: =IF($J20="","",9) -> 9 | B20: =IF($J20="","",INDEX('Soru Havuzu'!$D$2:$D$1001,$J20)) -> Aşağıdakilerden hangisi bir doğal sayının küpü değildir? | C20: =IF($J20="","",INDEX('Soru Havuzu'!$E$2:$E$1001,$J20)) -> 49 | D20: =IF($J20="","",INDEX('Soru Havuzu'!$F$2:$F$1001,$J20)) -> 27 | E20: =IF($J20="","",INDEX('Soru Havuzu'!$G$2:$G$1001,$J20)) -> 512 | F20: =IF($J20="","",INDEX('Soru Havuzu'!$H$2:$H$1001,$J20)) -> 8 | G20: =IF($J20="","",INDEX('Soru Havuzu'!$B$2:$B$1001,$J20)) -> Sayının Küpü | H20: =IF($J20="","",INDEX('Soru Havuzu'!$C$2:$C$1001,$J20)) -> Orta | J20: =IF(9<=MIN($B$3,$B$6),MATCH(9,'Soru Havuzu'!$L$2:$L$1001,0),"") -> 67
A21: =IF($J21="","",10) -> 10 | B21: =IF($J21="","",INDEX('Soru Havuzu'!$D$2:$D$1001,$J21)) -> Bir ayrıtı 9 cm olan küpün hacmi kaç cm³'tür? | C21: =IF($J21="","",INDEX('Soru Havuzu'!$E$2:$E$1001,$J21)) -> 27 | D21: =IF($J21="","",INDEX('Soru Havuzu'!$F$2:$F$1001,$J21)) -> 486 | E21: =IF($J21="","",INDEX('Soru Havuzu'!$G$2:$G$1001,$J21)) -> 81 | F21: =IF($J21="","",INDEX('Soru Havuzu'!$H$2:$H$1001,$J21)) -> 729 | G21: =IF($J21="","",INDEX('Soru Havuzu'!$B$2:$B$1001,$J21)) -> Küpün Hacmi | H21: =IF($J21="","",INDEX('Soru Havuzu'!$C$2:$C$1001,$J21)) -> Kolay | J21: =IF(10<=MIN($B$3,$B$6),MATCH(10,'Soru Havuzu'!$L$2:$L$1001,0),"") -> 111
A22: =IF($J22="","",11) | B22: =IF($J22="","",INDEX('Soru Havuzu'!$D$2:$D$1001,$J22)) | C22: =IF($J22="","",INDEX('Soru Havuzu'!$E$2:$E$1001,$J22)) | D22: =IF($J22="","",INDEX('Soru Havuzu'!$F$2:$F$1001,$J22)) | E22: =IF($J22="","",INDEX('Soru Havuzu'!$G$2:$G$1001,$J22)) | F22: =IF($J22="","",INDEX('Soru Havuzu'!$H$2:$H$1001,$J22)) | G22: =IF($J22="","",INDEX('Soru Havuzu'!$B$2:$B$1001,$J22)) | H22: =IF($J22="","",INDEX('Soru Havuzu'!$C$2:$C$1001,$J22)) | J22: =IF(11<=MIN($B$3,$B$6),MATCH(11,'Soru Havuzu'!$L$2:$L$1001,0),"")
A23: =IF($J23="","",12) | B23: =IF($J23="","",INDEX('Soru Havuzu'!$D$2:$D$1001,$J23)) | C23: =IF($J23="","",INDEX('Soru Havuzu'!$E$2:$E$1001,$J23)) | D23: =IF($J23="","",INDEX('Soru Havuzu'!$F$2:$F$1001,$J23)) | E23: =IF($J23="","",INDEX('Soru Havuzu'!$G$2:$G$1001,$J23)) | F23: =IF($J23="","",INDEX('Soru Havuzu'!$H$2:$H$1001,$J23)) | G23: =IF($J23="","",INDEX('Soru Havuzu'!$B$2:$B$1001,$J23)) | H23: =IF($J23="","",INDEX('Soru Havuzu'!$C$2:$C$1001,$J23)) | J23: =IF(12<=MIN($B$3,$B$6),MATCH(12,'Soru Havuzu'!$L$2:$L$1001,0),"")
A24: =IF($J24="","",13) | B24: =IF($J24="","",INDEX('Soru Havuzu'!$D$2:$D$1001,$J24)) | C24: =IF($J24="","",INDEX('Soru Havuzu'!$E$2:$E$1001,$J24)) | D24: =IF($J24="","",INDEX('Soru Havuzu'!$F$2:$F$1001,$J24)) | E24: =IF($J24="","",INDEX('Soru Havuzu'!$G$2:$G$1001,$J24)) | F24: =IF($J24="","",INDEX('Soru Havuzu'!$H$2:$H$1001,$J24)) | G24: =IF($J24="","",INDEX('Soru Havuzu'!$B$2:$B$1001,$J24)) | H24: =IF($J24="","",INDEX('Soru Havuzu'!$C$2:$C$1001,$J24)) | J24: =IF(13<=MIN($B$3,$B$6),MATCH(13,'Soru Havuzu'!$L$2:$L$1001,0),"")
A25: =IF($J25="","",14) | B25: =IF($J25="","",INDEX('Soru Havuzu'!$D$2:$D$1001,$J25)) | C25: =IF($J25="","",INDEX('Soru Havuzu'!$E$2:$E$1001,$J25)) | D25: =IF($J25="","",INDEX('Soru Havuzu'!$F$2:$F$1001,$J25)) | E25: =IF($J25="","",INDEX('Soru Havuzu'!$G$2:$G$1001,$J25)) | F25: =IF($J25="","",INDEX('Soru Havuzu'!$H$2:$H$1001,$J25)) | G25: =IF($J25="","",INDEX('Soru Havuzu'!$B$2:$B$1001,$J25)) | H25: =IF($J25="","",INDEX('Soru Havuzu'!$C$2:$C$1001,$J25)) | J25: =IF(14<=MIN($B$3,$B$6),MATCH(14,'Soru Havuzu'!$L$2:$L$1001,0),"")
A26: =IF($J26="","",15) | B26: =IF($J26="","",INDEX('Soru Havuzu'!$D$2:$D$1001,$J26)) | C26: =IF($J26="","",INDEX('Soru Havuzu'!$E$2:$E$1001,$J26)) | D26: =IF($J26="","",INDEX('Soru Havuzu'!$F$2:$F$1001,$J26)) | E26: =IF($J26="","",INDEX('Soru Havuzu'!$G$2:$G$1001,$J26)) | F26: =IF($J26="","",INDEX('Soru Havuzu'!$H$2:$H$1001,$J26)) | G26: =IF($J26="","",INDEX('Soru Havuzu'!$B$2:$B$1001,$J26)) | H26: =IF($J26="","",INDEX('Soru Havuzu'!$C$2:$C$1001,$J26)) | J26: =IF(15<=MIN($B$3,$B$6),MATCH(15,'Soru Havuzu'!$L$2:$L$1001,0),"")
A27: =IF($J27="","",16) | B27: =IF($J27="","",INDEX('Soru Havuzu'!$D$2:$D$1001,$J27)) | C27: =IF($J27="","",INDEX('Soru Havuzu'!$E$2:$E$1001,$J27)) | D27: =IF($J27="","",INDEX('Soru Havuzu'!$F$2:$F$1001,$J27)) | E27: =IF($J27="","",INDEX('Soru Havuzu'!$G$2:$G$1001,$J27)) | F27: =IF($J27="","",INDEX('Soru Havuzu'!$H$2:$H$1001,$J27)) | G27: =IF($J27="","",INDEX('Soru Havuzu'!$B$2:$B$1001,$J27)) | H27: =IF($J27="","",INDEX('Soru Havuzu'!$C$2:$C$1001,$J27)) | J27: =IF(16<=MIN($B$3,$B$6),MATCH(16,'Soru Havuzu'!$L$2:$L$1001,0),"")
A28: =IF($J28="","",17) | B28: =IF($J28="","",INDEX('Soru Havuzu'!$D$2:$D$1001,$J28)) | C28: =IF($J28="","",INDEX('Soru Havuzu'!$E$2:$E$1001,$J28)) | D28: =IF($J28="","",INDEX('Soru Havuzu'!$F$2:$F$1001,$J28)) | E28: =IF($J28="","",INDEX('Soru Havuzu'!$G$2:$G$1001,$J28)) | F28: =IF($J28="","",INDEX('Soru Havuzu'!$H$2:$H$1001,$J28)) | G28: =IF($J28="","",INDEX('Soru Havuzu'!$B$2:$B$1001,$J28)) | H28: =IF($J28="","",INDEX('Soru Havuzu'!$C$2:$C$1001,$J28)) | J28: =IF(17<=MIN($B$3,$B$6),MATCH(17,'Soru Havuzu'!$L$2:$L$1001,0),"")
A29: =IF($J29="","",18) | B29: =IF($J29="","",INDEX('Soru Havuzu'!$D$2:$D$1001,$J29)) | C29: =IF($J29="","",INDEX('Soru Havuzu'!$E$2:$E$1001,$J29)) | D29: =IF($J29="","",INDEX('Soru Havuzu'!$F$2:$F$1001,$J29)) | E29: =IF($J29="","",INDEX('Soru Havuzu'!$G$2:$G$1001,$J29)) | F29: =IF($J29="","",INDEX('Soru Havuzu'!$H$2:$H$1001,$J29)) | G29: =IF($J29="","",INDEX('Soru Havuzu'!$B$2:$B$1001,$J29)) | H29: =IF($J29="","",INDEX('Soru Havuzu'!$C$2:$C$1001,$J29)) | J29: =IF(18<=MIN($B$3,$B$6),MATCH(18,'Soru Havuzu'!$L$2:$L$1001,0),"")
A30: =IF($J30="","",19) | B30: =IF($J30="","",INDEX('Soru Havuzu'!$D$2:$D$1001,$J30)) | C30: =IF($J30="","",INDEX('Soru Havuzu'!$E$2:$E$1001,$J30)) | D30: =IF($J30="","",INDEX('Soru Havuzu'!$F$2:$F$1001,$J30)) | E30: =IF($J30="","",INDEX('Soru Havuzu'!$G$2:$G$1001,$J30)) | F30: =IF($J30="","",INDEX('Soru Havuzu'!$H$2:$H$1001,$J30)) | G30: =IF($J30="","",INDEX('Soru Havuzu'!$B$2:$B$1001,$J30)) | H30: =IF($J30="","",INDEX('Soru Havuzu'!$C$2:$C$1001,$J30)) | J30: =IF(19<=MIN($B$3,$B$6),MATCH(19,'Soru Havuzu'!$L$2:$L$1001,0),"")
A31: =IF($J31="","",20) | B31: =IF($J31="","",INDEX('Soru Havuzu'!$D$2:$D$1001,$J31)) | C31: =IF($J31="","",INDEX('Soru Havuzu'!$E$2:$E$1001,$J31)) | D31: =IF($J31="","",INDEX('Soru Havuzu'!$F$2:$F$1001,$J31)) | E31: =IF($J31="","",INDEX('Soru Havuzu'!$G$2:$G$1001,$J31)) | F31: =IF($J31="","",INDEX('Soru Havuzu'!$H$2:$H$1001,$J31)) | G31: =IF($J31="","",INDEX('Soru Havuzu'!$B$2:$B$1001,$J31)) | H31: =IF($J31="","",INDEX('Soru Havuzu'!$C$2:$C$1001,$J31)) | J31: =IF(20<=MIN($B$3,$B$6),MATCH(20,'Soru Havuzu'!$L$2:$L$1001,0),"")
A32: =IF($J32="","",21) | B32: =IF($J32="","",INDEX('Soru Havuzu'!$D$2:$D$1001,$J32)) | C32: =IF($J32="","",INDEX('Soru Havuzu'!$E$2:$E$1001,$J32)) | D32: =IF($J32="","",INDEX('Soru Havuzu'!$F$2:$F$1001,$J32)) | E32: =IF($J32="","",INDEX('Soru Havuzu'!$G$2:$G$1001,$J32)) | F32: =IF($J32="","",INDEX('Soru Havuzu'!$H$2:$H$1001,$J32)) | G32: =IF($J32="","",INDEX('Soru Havuzu'!$B$2:$B$1001,$J32)) | H32: =IF($J32="","",INDEX('Soru Havuzu'!$C$2:$C$1001,$J32)) | J32: =IF(21<=MIN($B$3,$B$6),MATCH(21,'Soru Havuzu'!$L$2:$L$1001,0),"")
A33: =IF($J33="","",22) | B33: =IF($J33="","",INDEX('Soru Havuzu'!$D$2:$D$1001,$J33)) | C33: =IF($J33="","",INDEX('Soru Havuzu'!$E$2:$E$1001,$J33)) | D33: =IF($J33="","",INDEX('Soru Havuzu'!$F$2:$F$1001,$J33)) | E33: =IF($J33="","",INDEX('Soru Havuzu'!$G$2:$G$1001,$J33)) | F33: =IF($J33="","",INDEX('Soru Havuzu'!$H$2:$H$1001,$J33)) | G33: =IF($J33="","",INDEX('Soru Havuzu'!$B$2:$B$1001,$J33)) | H33: =IF($J33="","",INDEX('Soru Havuzu'!$C$2:$C$1001,$J33)) | J33: =IF(22<=MIN($B$3,$B$6),MATCH(22,'Soru Havuzu'!$L$2:$L$1001,0),"")
A34: =IF($J34="","",23) | B34: =IF($J34="","",INDEX('Soru Havuzu'!$D$2:$D$1001,$J34)) | C34: =IF($J34="","",INDEX('Soru Havuzu'!$E$2:$E$1001,$J34)) | D34: =IF($J34="","",INDEX('Soru Havuzu'!$F$2:$F$1001,$J34)) | E34: =IF($J34="","",INDEX('Soru Havuzu'!$G$2:$G$1001,$J34)) | F34: =IF($J34="","",INDEX('Soru Havuzu'!$H$2:$H$1001,$J34)) | G34: =IF($J34="","",INDEX('Soru Havuzu'!$B$2:$B$1001,$J34)) | H34: =IF($J34="","",INDEX('Soru Havuzu'!$C$2:$C$1001,$J34)) | J34: =IF(23<=MIN($B$3,$B$6),MATCH(23,'Soru Havuzu'!$L$2:$L$1001,0),"")
A35: =IF($J35="","",24) | B35: =IF($J35="","",INDEX('Soru Havuzu'!$D$2:$D$1001,$J35)) | C35: =IF($J35="","",INDEX('Soru Havuzu'!$E$2:$E$1001,$J35)) | D35: =IF($J35="","",INDEX('Soru Havuzu'!$F$2:$F$1001,$J35)) | E35: =IF($J35="","",INDEX('Soru Havuzu'!$G$2:$G$1001,$J35)) | F35: =IF($J35="","",INDEX('Soru Havuzu'!$H$2:$H$1001,$J35)) | G35: =IF($J35="","",INDEX('Soru Havuzu'!$B$2:$B$1001,$J35)) | H35: =IF($J35="","",INDEX('Soru Havuzu'!$C$2:$C$1001,$J35)) | J35: =IF(24<=MIN($B$3,$B$6),MATCH(24,'Soru Havuzu'!$L$2:$L$1001,0),"")
A36: =IF($J36="","",25) | B36: =IF($J36="","",INDEX('Soru Havuzu'!$D$2:$D$1001,$J36)) | C36: =IF($J36="","",INDEX('Soru Havuzu'!$E$2:$E$1001,$J36)) | D36: =IF($J36="","",INDEX('Soru Havuzu'!$F$2:$F$1001,$J36)) | E36: =IF($J36="","",INDEX('Soru Havuzu'!$G$2:$G$1001,$J36)) | F36: =IF($J36="","",INDEX('Soru Havuzu'!$H$2:$H$1001,$J36)) | G36: =IF($J36="","",INDEX('Soru Havuzu'!$B$2:$B$1001,$J36)) | H36: =IF($J36="","",INDEX('Soru Havuzu'!$C$2:$C$1001,$J36)) | J36: =IF(25<=MIN($B$3,$B$6),MATCH(25,'Soru Havuzu'!$L$2:$L$1001,0),"")
A37: =IF($J37="","",26) | B37: =IF($J37="","",INDEX('Soru Havuzu'!$D$2:$D$1001,$J37)) | C37: =IF($J37="","",INDEX('Soru Havuzu'!$E$2:$E$1001,$J37)) | D37: =IF($J37="","",INDEX('Soru Havuzu'!$F$2:$F$1001,$J37)) | E37: =IF($J37="","",INDEX('Soru Havuzu'!$G$2:$G$1001,$J37)) | F37: =IF($J37="","",INDEX('Soru Havuzu'!$H$2:$H$1001,$J37)) | G37: =IF($J37="","",INDEX('Soru Havuzu'!$B$2:$B$1001,$J37)) | H37: =IF($J37="","",INDEX('Soru Havuzu'!$C$2:$C$1001,$J37)) | J37: =IF(26<=MIN($B$3,$B$6),MATCH(26,'Soru Havuzu'!$L$2:$L$1001,0),"")
A38: =IF($J38="","",27) | B38: =IF($J38="","",INDEX('Soru Havuzu'!$D$2:$D$1001,$J38)) | C38: =IF($J38="","",INDEX('Soru Havuzu'!$E$2:$E$1001,$J38)) | D38: =IF($J38="","",INDEX('Soru Havuzu'!$F$2:$F$1001,$J38)) | E38: =IF($J38="","",INDEX('Soru Havuzu'!$G$2:$G$1001,$J38)) | F38: =IF($J38="","",INDEX('Soru Havuzu'!$H$2:$H$1001,$J38)) | G38: =IF($J38="","",INDEX('Soru Havuzu'!$B$2:$B$1001,$J38)) | H38: =IF($J38="","",INDEX('Soru Havuzu'!$C$2:$C$1001,$J38)) | J38: =IF(27<=MIN($B$3,$B$6),MATCH(27,'Soru Havuzu'!$L$2:$L$1001,0),"")
A39: =IF($J39="","",28) | B39: =IF($J39="","",INDEX('Soru Havuzu'!$D$2:$D$1001,$J39)) | C39: =IF($J39="","",INDEX('Soru Havuzu'!$E$2:$E$1001,$J39)) | D39: =IF($J39="","",INDEX('Soru Havuzu'!$F$2:$F$1001,$J39)) | E39: =IF($J39="","",INDEX('Soru Havuzu'!$G$2:$G$1001,$J39)) | F39: =IF($J39="","",INDEX('Soru Havuzu'!$H$2:$H$1001,$J39)) | G39: =IF($J39="","",INDEX('Soru Havuzu'!$B$2:$B$1001,$J39)) | H39: =IF($J39="","",INDEX('Soru Havuzu'!$C$2:$C$1001,$J39)) | J39: =IF(28<=MIN($B$3,$B$6),MATCH(28,'Soru Havuzu'!$L$2:$L$1001,0),"")
A40: =IF($J40="","",29) | B40: =IF($J40="","",INDEX('Soru Havuzu'!$D$2:$D$1001,$J40)) | C40: =IF($J40="","",INDEX('Soru Havuzu'!$E$2:$E$1001,$J40)) | D40: =IF($J40="","",INDEX('Soru Havuzu'!$F$2:$F$1001,$J40)) | E40: =IF($J40="","",INDEX('Soru Havuzu'!$G$2:$G$1001,$J40)) | F40: =IF($J40="","",INDEX('Soru Havuzu'!$H$2:$H$1001,$J40)) | G40: =IF($J40="","",INDEX('Soru Havuzu'!$B$2:$B$1001,$J40)) | H40: =IF($J40="","",INDEX('Soru Havuzu'!$C$2:$C$1001,$J40)) | J40: =IF(29<=MIN($B$3,$B$6),MATCH(29,'Soru Havuzu'!$L$2:$L$1001,0),"")
A41: =IF($J41="","",30) | B41: =IF($J41="","",INDEX('Soru Havuzu'!$D$2:$D$1001,$J41)) | C41: =IF($J41="","",INDEX('Soru Havuzu'!$E$2:$E$1001,$J41)) | D41: =IF($J41="","",INDEX('Soru Havuzu'!$F$2:$F$1001,$J41)) | E41: =IF($J41="","",INDEX('Soru Havuzu'!$G$2:$G$1001,$J41)) | F41: =IF($J41="","",INDEX('Soru Havuzu'!$H$2:$H$1001,$J41)) | G41: =IF($J41="","",INDEX('Soru Havuzu'!$B$2:$B$1001,$J41)) | H41: =IF($J41="","",INDEX('Soru Havuzu'!$C$2:$C$1001,$J41)) | J41: =IF(30<=MIN($B$3,$B$6),MATCH(30,'Soru Havuzu'!$L$2:$L$1001,0),"")
A42: =IF($J42="","",31) | B42: =IF($J42="","",INDEX('Soru Havuzu'!$D$2:$D$1001,$J42)) | C42: =IF($J42="","",INDEX('Soru Havuzu'!$E$2:$E$1001,$J42)) | D42: =IF($J42="","",INDEX('Soru Havuzu'!$F$2:$F$1001,$J42)) | E42: =IF($J42="","",INDEX('Soru Havuzu'!$G$2:$G$1001,$J42)) | F42: =IF($J42="","",INDEX('Soru Havuzu'!$H$2:$H$1001,$J42)) | G42: =IF($J42="","",INDEX('Soru Havuzu'!$B$2:$B$1001,$J42)) | H42: =IF($J42="","",INDEX('Soru Havuzu'!$C$2:$C$1001,$J42)) | J42: =IF(31<=MIN($B$3,$B$6),MATCH(31,'Soru Havuzu'!$L$2:$L$1001,0),"")
A43: =IF($J43="","",32) | B43: =IF($J43="","",INDEX('Soru Havuzu'!$D$2:$D$1001,$J43)) | C43: =IF($J43="","",INDEX('Soru Havuzu'!$E$2:$E$1001,$J43)) | D43: =IF($J43="","",INDEX('Soru Havuzu'!$F$2:$F$1001,$J43)) | E43: =IF($J43="","",INDEX('Soru Havuzu'!$G$2:$G$1001,$J43)) | F43: =IF($J43="","",INDEX('Soru Havuzu'!$H$2:$H$1001,$J43)) | G43: =IF($J43="","",INDEX('Soru Havuzu'!$B$2:$B$1001,$J43)) | H43: =IF($J43="","",INDEX('Soru Havuzu'!$C$2:$C$1001,$J43)) | J43: =IF(32<=MIN($B$3,$B$6),MATCH(32,'Soru Havuzu'!$L$2:$L$1001,0),"")
...

Sheet Soru Havuzu
A1: No | B1: Konu | C1: Zorluk | D1: Soru | E1: A | F1: B | G1: C | H1: D | I1: Doğru Şık | J1: Uygun | K1: Rastgele | L1: Sıra
A2: 1 | B2: Sayının Küpü | C2: Kolay | D2: 1³ ifadesinin değeri kaçtır? | E2: 4 | F2: 1 | G2: 2 | H2: 3 | I2: B | J2: =IF($D2="",0,IF(AND(OR(Test!$B$4="Hepsi",$B2=Test!$B$4),OR(Test!$B$5="Hepsi",$C2=Test!$B$5)),1,0)) -> 1 | K2: =IF($J2=1,RAND(),-1) -> 0.04117541 | L2: =IF($J2=1,RANK($K2,$K$2:$K$1001),"") -> 217
A3: 2 | B3: Sayının Küpü | C3: Kolay | D3: 2³ ifadesinin değeri kaçtır? | E3: 6 | F3: 8 | G3: 10 | H3: 4 | I3: B | J3: =IF($D3="",0,IF(AND(OR(Test!$B$4="Hepsi",$B3=Test!$B$4),OR(Test!$B$5="Hepsi",$C3=Test!$B$5)),1,0)) -> 1 | K3: =IF($J3=1,RAND(),-1) -> 0.44941119 | L3: =IF($J3=1,RANK($K3,$K$2:$K$1001),"") -> 132
A4: 3 | B4: Sayının Küpü | C4: Kolay | D4: 3³ ifadesinin değeri kaçtır? | E4: 9 | F4: 30 | G4: 6 | H4: 27 | I4: D | J4: =IF($D4="",0,IF(AND(OR(Test!$B$4="Hepsi",$B4=Test!$B$4),OR(Test!$B$5="Hepsi",$C4=Test!$B$5)),1,0)) -> 1 | K4: =IF($J4=1,RAND(),-1) -> 0.60109649 | L4: =IF($J4=1,RANK($K4,$K$2:$K$1001),"") -> 98
A5: 4 | B5: Sayının Küpü | C5: Kolay | D5: 4³ ifadesinin değeri kaçtır? | E5: 64 | F5: 68 | G5: 12 | H5: 16 | I5: A | J5: =IF($D5="",0,IF(AND(OR(Test!$B$4="Hepsi",$B5=Test!$B$4),OR(Test!$B$5="Hepsi",$C5=Test!$B$5)),1,0)) -> 1 | K5: =IF($J5=1,RAND(),-1) -> 0.83030833 | L5: =IF($J5=1,RANK($K5,$K$2:$K$1001),"") -> 44
A6: 5 | B6: Sayının Küpü | C6: Kolay | D6: 5³ ifadesinin değeri kaçtır? | E6: 130 | F6: 125 | G6: 25 | H6: 15 | I6: B | J6: =IF($D6="",0,IF(AND(OR(Test!$B$4="Hepsi",$B6=Test!$B$4),OR(Test!$B$5="Hepsi",$C6=Test!$B$5)),1,0)) -> 1 | K6: =IF($J6=1,RAND(),-1) -> 0.86892368 | L6: =IF($J6=1,RANK($K6,$K$2:$K$1001),"") -> 35
A7: 6 | B7: Sayının Küpü | C7: Kolay | D7: 6³ ifadesinin değeri kaçtır? | E7: 222 | F7: 36 | G7: 18 | H7: 216 | I7: D | J7: =IF($D7="",0,IF(AND(OR(Test!$B$4="Hepsi",$B7=Test!$B$4),OR(Test!$B$5="Hepsi",$C7=Test!$B$5)),1,0)) -> 1 | K7: =IF($J7=1,RAND(),-1) -> 0.028367544 | L7: =IF($J7=1,RANK($K7,$K$2:$K$1001),"") -> 221
A8: 7 | B8: Sayının Küpü | C8: Kolay | D8: 7³ ifadesinin değeri kaçtır? | E8: 343 | F8: 49 | G8: 21 | H8: 350 | I8: A | J8: =IF($D8="",0,IF(AND(OR(Test!$B$4="Hepsi",$B8=Test!$B$4),OR(Test!$B$5="Hepsi",$C8=Test!$B$5)),1,0)) -> 1 | K8: =IF($J8=1,RAND(),-1) -> 0.99963405 | L8: =IF($J8=1,RANK($K8,$K$2:$K$1001),"") -> 2
A9: 8 | B9: Sayının Küpü | C9: Kolay | D9: 8³ ifadesinin değeri kaçtır? | E9: 24 | F9: 512 | G9: 64 | H9: 520 | I9: B | J9: =IF($D9="",0,IF(AND(OR(Test!$B$4="Hepsi",$B9=Test!$B$4),OR(Test!$B$5="Hepsi",$C9=Test!$B$5)),1,0)) -> 1 | K9: =IF($J9=1,RAND(),-1) -> 0.35386319 | L9: =IF($J9=1,RANK($K9,$K$2:$K$1001),"") -> 155
A10: 9 | B10: Sayının Küpü | C10: Kolay | D10: 9³ ifadesinin değeri kaçtır? | E10: 81 | F10: 27 | G10: 738 | H10: 729 | I10: D | J10: =IF($D10="",0,IF(AND(OR(Test!$B$4="Hepsi",$B10=Test!$B$4),OR(Test!$B$5="Hepsi",$C10=Test!$B$5)),1,0)) -> 1 | K10: =IF($J10=1,RAND(),-1) -> 0.94117966 | L10: =IF($J10=1,RANK($K10,$K$2:$K$1001),"") -> 21
A11: 10 | B11: Sayının Küpü | C11: Kolay | D11: 10³ ifadesinin değeri kaçtır? | E11: 1000 | F11: 100 | G11: 30 | H11: 1010 | I11: A | J11: =IF($D11="",0,IF(AND(OR(Test!$B$4="Hepsi",$B11=Test!$B$4),OR(Test!$B$5="Hepsi",$C11=Test!$B$5)),1,0)) -> 1 | K11: =IF($J11=1,RAND(),-1) -> 0.31630263 | L11: =IF($J11=1,RANK($K11,$K$2:$K$1001),"") -> 163
A12: 11 | B12: Sayının Küpü | C12: Kolay | D12: 2 · 2 · 2 çarpımının üslü gösterimi hangisidir? | E12: 2³ | F12: 3² | G12: 2² | H12: 2 · 3 | I12: A | J12: =IF($D12="",0,IF(AND(OR(Test!$B$4="Hepsi",$B12=Test!$B$4),OR(Test!$B$5="Hepsi",$C12=Test!$B$5)),1,0)) -> 1 | K12: =IF($J12=1,RAND(),-1) -> 0.14685472 | L12: =IF($J12=1,RANK($K12,$K$2:$K$1001),"") -> 195
A13: 12 | B13: Sayının Küpü | C13: Kolay | D13: 3 · 3 · 3 çarpımının üslü gösterimi hangisidir? | E13: 3³ | F13: 3 · 3 | G13: 3² | H13: 3⁴ | I13: A | J13: =IF($D13="",0,IF(AND(OR(Test!$B$4="Hepsi",$B13=Test!$B$4),OR(Test!$B$5="Hepsi",$C13=Test!$B$5)),1,0)) -> 1 | K13: =IF($J13=1,RAND(),-1) -> 0.31813579 | L13: =IF($J13=1,RANK($K13,$K$2:$K$1001),"") -> 162
... A225: 224 | B225: Küpün Özellikleri | C225: Zor | D225: Birim küplerden oluşan bir küpün dış yüzeyi boyanıyor. 3 yüzü boyalı kaç birim küp vardır? | E225: 8 | F225: 4 | G225: 12 | H225: 6 | I225: A | J225: =IF($D225="",0,IF(AND(OR(Test!$B$4="Hepsi",$B225=Test!$B$4),OR(Test!$B$5="Hepsi",$C225=Test!$B$5)),1,0)) -> 1 | K225: =IF($J225=1,RAND(),-1) -> 0.89425728 | L225: =IF($J225=1,RANK($K225,$K$2:$K$1001),"") -> 30
J226: =IF($D226="",0,IF(AND(OR(Test!$B$4="Hepsi",$B226=Test!$B$4),OR(Test!$B$5="Hepsi",$C226=Test!$B$5)),1,0)) -> 0 | K226: =IF($J226=1,RAND(),-1) -> -1 | L226: =IF($J226=1,RANK($K226,$K$2:$K$1001),"")
J227: =IF($D227="",0,IF(AND(OR(Test!$B$4="Hepsi",$B227=Test!$B$4),OR(Test!$B$5="Hepsi",$C227=Test!$B$5)),1,0)) -> 0 | K227: =IF($J227=1,RAND(),-1) -> -1 | L227: =IF($J227=1,RANK($K227,$K$2:$K$1001),"")
J228: =IF($D228="",0,IF(AND(OR(Test!$B$4="Hepsi",$B228=Test!$B$4),OR(Test!$B$5="Hepsi",$C228=Test!$B$5)),1,0)) -> 0 | K228: =IF($J228=1,RAND(),-1) -> -1 | L228: =IF($J228=1,RANK($K228,$K$2:$K$1001),"")
J229: =IF($D229="",0,IF(AND(OR(Test!$B$4="Hepsi",$B229=Test!$B$4),OR(Test!$B$5="Hepsi",$C229=Test!$B$5)),1,0)) -> 0 | K229: =IF($J229=1,RAND(),-1) -> -1 | L229: =IF($J229=1,RANK($K229,$K$2:$K$1001),"")
J230: =IF($D230="",0,IF(AND(OR(Test!$B$4="Hepsi",$B230=Test!$B$4),OR(Test!$B$5="Hepsi",$C230=Test!$B$5)),1,0)) -> 0 | K230: =IF($J230=1,RAND(),-1) -> -1 | L230: =IF($J230=1,RANK($K230,$K$2:$K$1001),"")
J231: =IF($D231="",0,IF(AND(OR(Test!$B$4="Hepsi",$B231=Test!$B$4),OR(Test!$B$5="Hepsi",$C231=Test!$B$5)),1,0)) -> 0 | K231: =IF($J231=1,RAND(),-1) -> -1 | L231: =IF($J231=1,RANK($K231,$K$2:$K$1001),"")
J232: =IF($D232="",0,IF(AND(OR(Test!$B$4="Hepsi",$B232=Test!$B$4),OR(Test!$B$5="Hepsi",$C232=Test!$B$5)),1,0)) -> 0 | K232: =IF($J232=1,RAND(),-1) -> -1 | L232: =IF($J232=1,RANK($K232,$K$2:$K$1001),"")
J233: =IF($D233="",0,IF(AND(OR(Test!$B$4="Hepsi",$B233=Test!$B$4),OR(Test!$B$5="Hepsi",$C233=Test!$B$5)),1,0)) -> 0 | K233: =IF($J233=1,RAND(),-1) -> -1 | L233: =IF($J233=1,RANK($K233,$K$2:$K$1001),"")
J234: =IF($D234="",0,IF(AND(OR(Test!$B$4="Hepsi",$B234=Test!$B$4),OR(Test!$B$5="Hepsi",$C234=Test!$B$5)),1,0)) -> 0 | K234: =IF($J234=1,RAND(),-1) -> -1 | L234: =IF($J234=1,RANK($K234,$K$2:$K$1001),"")
J235: =IF($D235="",0,IF(AND(OR(Test!$B$4="Hepsi",$B235=Test!$B$4),OR(Test!$B$5="Hepsi",$C235=Test!$B$5)),1,0)) -> 0 | K235: =IF($J235=1,RAND(),-1) -> -1 | L235: =IF($J235=1,RANK($K235,$K$2:$K$1001),"")
J236: =IF($D236="",0,IF(AND(OR(Test!$B$4="Hepsi",$B236=Test!$B$4),OR(Test!$B$5="Hepsi",$C236=Test!$B$5)),1,0)) -> 0 | K236: =IF($J236=1,RAND(),-1) -> -1 | L236: =IF($J236=1,RANK($K236,$K$2:$K$1001),"")
J237: =IF($D237="",0,IF(AND(OR(Test!$B$4="Hepsi",$B237=Test!$B$4),OR(Test!$B$5="Hepsi",$C237=Test!$B$5)),1,0)) -> 0 | K237: =IF($J237=1,RAND(),-1) -> -1 | L237: =IF($J237=1,RANK($K237,$K$2:$K$1001),"")
... J1001: =IF($D1001="",0,IF(AND(OR(Test!$B$4="Hepsi",$B1001=Test!$B$4),OR(Test!$B$5="Hepsi",$C1001=Test!$B$5)),1,0)) -> 0 | K1001: =IF($J1001=1,RAND(),-1) -> -1 | L1001: =IF($J1001=1,RANK($K1001,$K$2:$K$1001),"")

Sheet Cevap Anahtarı
A1: CEVAP ANAHTARI
A3: No | B3: Doğru Şık | C3: Cevap
A4: =Test!A12 -> 1 | B4: =IF(Test!$J12="","",INDEX('Soru Havuzu'!$I$2:$I$1001,Test!$J12)) -> B | C4: =IF(B4="","",INDEX(Test!$C12:$F12,MATCH(B4,{"A","B","C","D"},0))) -> 24
A5: =Test!A13 -> 2 | B5: =IF(Test!$J13="","",INDEX('Soru Havuzu'!$I$2:$I$1001,Test!$J13)) -> A | C5: =IF(B5="","",INDEX(Test!$C13:$F13,MATCH(B5,{"A","B","C","D"},0))) -> 343
A6: =Test!A14 -> 3 | B6: =IF(Test!$J14="","",INDEX('Soru Havuzu'!$I$2:$I$1001,Test!$J14)) -> C | C6: =IF(B6="","",INDEX(Test!$C14:$F14,MATCH(B6,{"A","B","C","D"},0))) -> 84
A7: =Test!A15 -> 4 | B7: =IF(Test!$J15="","",INDEX('Soru Havuzu'!$I$2:$I$1001,Test!$J15)) -> A | C7: =IF(B7="","",INDEX(Test!$C15:$F15,MATCH(B7,{"A","B","C","D"},0))) -> 2
A8: =Test!A16 -> 5 | B8: =IF(Test!$J16="","",INDEX('Soru Havuzu'!$I$2:$I$1001,Test!$J16)) -> D | C8: =IF(B8="","",INDEX(Test!$C16:$F16,MATCH(B8,{"A","B","C","D"},0))) -> 64
A9: =Test!A17 -> 6 | B9: =IF(Test!$J17="","",INDEX('Soru Havuzu'!$I$2:$I$1001,Test!$J17)) -> D | C9: =IF(B9="","",INDEX(Test!$C17:$F17,MATCH(B9,{"A","B","C","D"},0))) -> 10²
A10: =Test!A18 -> 7 | B10: =IF(Test!$J18="","",INDEX('Soru Havuzu'!$I$2:$I$1001,Test!$J18)) -> C | C10: =IF(B10="","",INDEX(Test!$C18:$F18,MATCH(B10,{"A","B","C","D"},0))) -> 6 · 6 · 6
A11: =Test!A19 -> 8 | B11: =IF(Test!$J19="","",INDEX('Soru Havuzu'!$I$2:$I$1001,Test!$J19)) -> D | C11: =IF(B11="","",INDEX(Test!$C19:$F19,MATCH(B11,{"A","B","C","D"},0))) -> 9²
A12: =Test!A20 -> 9 | B12: =IF(Test!$J20="","",INDEX('Soru Havuzu'!$I$2:$I$1001,Test!$J20)) -> A | C12: =IF(B12="","",INDEX(Test!$C20:$F20,MATCH(B12,{"A","B","C","D"},0))) -> 49
A13: =Test!A21 -> 10 | B13: =IF(Test!$J21="","",INDEX('Soru Havuzu'!$I$2:$I$1001,Test!$J21)) -> D | C13: =IF(B13="","",INDEX(Test!$C21:$F21,MATCH(B13,{"A","B","C","D"},0))) -> 729
A14: =Test!A22 | B14: =IF(Test!$J22="","",INDEX('Soru Havuzu'!$I$2:$I$1001,Test!$J22)) | C14: =IF(B14="","",INDEX(Test!$C22:$F22,MATCH(B14,{"A","B","C","D"},0)))
A15: =Test!A23 | B15: =IF(Test!$J23="","",INDEX('Soru Havuzu'!$I$2:$I$1001,Test!$J23)) | C15: =IF(B15="","",INDEX(Test!$C23:$F23,MATCH(B15,{"A","B","C","D"},0)))
... A103: =Test!A111 | B103: =IF(Test!$J111="","",INDEX('Soru Havuzu'!$I$2:$I$1001,Test!$J111)) | C103: =IF(B103="","",INDEX(Test!$C111:$F111,MATCH(B103,{"A","B","C","D"},0)))
